Workbook
Name retail_sales_dataset: 'Cleaned Data'!$A$1:$I$1001
Name retail_sales_dataset: Dataset!$A$1:$I$1001

Sheet Dataset
A1: Transaction ID | B1: Date | C1: Customer ID | D1: Gender | E1: Age | F1: Product Category | G1: Quantity | H1: Price per Unit | I1: Total Amount
A2: 1 | B2: 45254 | C2: CUST001 | D2: Male | E2: 34 | F2: Beauty | G2: 3 | H2: 50 | I2: 150
A3: 2 | B3: 44984 | C3: CUST002 | D3: Female | E3: 26 | F3: Clothing | G3: 2 | H3: 500 | I3: 1000
A4: 3 | B4: 44939 | C4: CUST003 | D4: Male | E4: 50 | F4: Electronics | G4: 1 | H4: 30 | I4: 30
A5: 4 | B5: =COUNT(Dataset!A1) -> 0 | C5: CUST004 | D5: Male | E5: 37 | F5: Clothing | G5: 1 | H5: 500 | I5: 500
A6: 5 | B6: 45052 | C6: CUST005 | D6: Male | E6: 30 | F6: Beauty | G6: 2 | H6: 50 | I6: 100
A7: 6 | B7: 45041 | C7: CUST006 | D7: Female | E7: 45 | F7: Beauty | G7: 1 | H7: 30 | I7: 30
A8: 7 | B8: 44998 | C8: CUST007 | D8: Male | E8: 46 | F8: Clothing | G8: 2 | H8: 25 | I8: 50
A9: 8 | B9: 44979 | C9: CUST008 | D9: Male | E9: 30 | F9: Electronics | G9: 4 | H9: 25 | I9: 100
A10: 9 | B10: 45273 | C10: CUST009 | D10: Male | E10: 63 | F10: Electronics | G10: 2 | H10: 300 | I10: 600
A11: 10 | B11: 45206 | C11: CUST010 | D11: Female | E11: 52 | F11: Clothing | G11: 4 | H11: 50 | I11: 200
A12: 11 | B12: 44971 | C12: CUST011 | D12: Male | E12: 23 | F12: Clothing | G12: 2 | H12: 50 | I12: 100
A13: 12 | B13: 45229 | C13: CUST012 | D13: Male | E13: 35 | F13: Beauty | G13: 3 | H13: 25 | I13: 75
A14: 13 | B14: 45143 | C14: CUST013 | D14: Male | E14: 22 | F14: Electronics | G14: 3 | H14: 500 | I14: 1500
A15: 14 | B15: 44943 | C15: CUST014 | D15: Male | E15: 64 | F15: Clothing | G15: 4 | H15: 30 | I15: 120
A16: 15 | B16: 44942 | C16: CUST015 | D16: Female | E16: 42 | F16: Electronics | G16: 4 | H16: 500 | I16: 2000
A17: 16 | B17: 44974 | C17: CUST016 | D17: Male | E17: 19 | F17: Clothing | G17: 3 | H17: 500 | I17: 1500
... A1001: 1000 | B1001: 45028 | C1001: CUST1000 | D1001: Male | E1001: 47 | F1001: Electronics | G1001: 4 | H1001: 30 | I1001: 120

Sheet Understanding of Data
A2: PART 1 : OPEN AND UNDERSTAND THE DATASET
A4: 1. How many rows are in the data set?
A5: Ans : | B5: =COUNT(Dataset!A:A) -> 1000
A6: 2. How many columns are in the data set?
A7: Ans : | B7: =COLUMNS('Understanding of Data'!A1:I1) -> 9
A8: 3. What type of data is stored in the Date column?
A9: Ans : | B9: date
A10: 4. What type of data is stored in the Product Category column?
A11: Ans : | B11: string
A12: 5. What type of data is stored in the Total Amount column?
A13: Ans : | B13: integer
A14: 6. What are the unique product categories available in the dataset?
A15: Ans : | B15: beauty, clothing, electronics
A16: 7. What are the minimum and maximum age of customers?
A17: Ans : | B17: =MIN(Dataset!E2:E1001) -> 18 | C17: (minimum)
B18: =MAX(Dataset!E2:E1001) -> 64 | C18: (maximum)

Sheet Cleaned Data
A1: Transaction ID | B1: Date | C1: Customer ID | D1: Gender | E1: Age | F1: Product Category | G1: Quantity | H1: Price per Unit | I1: Total Amount | J1: Calculated Total | K1: Amount Check | L1: Age Group
A2: 1 | B2: 45254 | C2: CUST001 | D2: Male | E2: 34 | F2: Beauty | G2: 3 | H2: 50 | I2: 150 | J2: =G2*H2 -> 150 | K2: =IF(I2=J2,"Correct","Check") -> Correct | L2: =IF(E2<=25,"Young Adult",IF(E2<=40,"Adult",IF(E2<=60,"Senior Adult","Older Customer"))) -> Adult
A3: 2 | B3: 44984 | C3: CUST002 | D3: Female | E3: 26 | F3: Clothing | G3: 2 | H3: 500 | I3: 1000 | J3: =G3*H3 -> 1000 | K3: =IF(I3=J3,"Correct","Check") -> Correct | L3: =IF(E3<=25,"Young Adult",IF(E3<=40,"Adult",IF(E3<=60,"Senior Adult","Older Customer"))) -> Adult
A4: 3 | B4: 44939 | C4: CUST003 | D4: Male | E4: 50 | F4: Electronics | G4: 1 | H4: 30 | I4: 30 | J4: =G4*H4 -> 30 | K4: =IF(I4=J4,"Correct","Check") -> Correct | L4: =IF(E4<=25,"Young Adult",IF(E4<=40,"Adult",IF(E4<=60,"Senior Adult","Older Customer"))) -> Senior Adult
A5: 4 | B5: =COUNT('Cleaned Data'!A1) -> 0 | C5: CUST004 | D5: Male | E5: 37 | F5: Clothing | G5: 1 | H5: 500 | I5: 500 | J5: =G5*H5 -> 500 | K5: =IF(I5=J5,"Correct","Check") -> Correct | L5: =IF(E5<=25,"Young Adult",IF(E5<=40,"Adult",IF(E5<=60,"Senior Adult","Older Customer"))) -> Adult
A6: 5 | B6: 45052 | C6: CUST005 | D6: Male | E6: 30 | F6: Beauty | G6: 2 | H6: 50 | I6: 100 | J6: =G6*H6 -> 100 | K6: =IF(I6=J6,"Correct","Check") -> Correct | L6: =IF(E6<=25,"Young Adult",IF(E6<=40,"Adult",IF(E6<=60,"Senior Adult","Older Customer"))) -> Adult
A7: 6 | B7: 45041 | C7: CUST006 | D7: Female | E7: 45 | F7: Beauty | G7: 1 | H7: 30 | I7: 30 | J7: =G7*H7 -> 30 | K7: =IF(I7=J7,"Correct","Check") -> Correct | L7: =IF(E7<=25,"Young Adult",IF(E7<=40,"Adult",IF(E7<=60,"Senior Adult","Older Customer"))) -> Senior Adult
A8: 7 | B8: 44998 | C8: CUST007 | D8: Male | E8: 46 | F8: Clothing | G8: 2 | H8: 25 | I8: 50 | J8: =G8*H8 -> 50 | K8: =IF(I8=J8,"Correct","Check") -> Correct | L8: =IF(E8<=25,"Young Adult",IF(E8<=40,"Adult",IF(E8<=60,"Senior Adult","Older Customer"))) -> Senior Adult
A9: 8 | B9: 44979 | C9: CUST008 | D9: Male | E9: 30 | F9: Electronics | G9: 4 | H9: 25 | I9: 100 | J9: =G9*H9 -> 100 | K9: =IF(I9=J9,"Correct","Check") -> Correct | L9: =IF(E9<=25,"Young Adult",IF(E9<=40,"Adult",IF(E9<=60,"Senior Adult","Older Customer"))) -> Adult
A10: 9 | B10: 45273 | C10: CUST009 | D10: Male | E10: 63 | F10: Electronics | G10: 2 | H10: 300 | I10: 600 | J10: =G10*H10 -> 600 | K10: =IF(I10=J10,"Correct","Check") -> Correct | L10: =IF(E10<=25,"Young Adult",IF(E10<=40,"Adult",IF(E10<=60,"Senior Adult","Older Customer"))) -> Older Customer
A11: 10 | B11: 45206 | C11: CUST010 | D11: Female | E11: 52 | F11: Clothing | G11: 4 | H11: 50 | I11: 200 | J11: =G11*H11 -> 200 | K11: =IF(I11=J11,"Correct","Check") -> Correct | L11: =IF(E11<=25,"Young Adult",IF(E11<=40,"Adult",IF(E11<=60,"Senior Adult","Older Customer"))) -> Senior Adult
A12: 11 | B12: 44971 | C12: CUST011 | D12: Male | E12: 23 | F12: Clothing | G12: 2 | H12: 50 | I12: 100 | J12: =G12*H12 -> 100 | K12: =IF(I12=J12,"Correct","Check") -> Correct | L12: =IF(E12<=25,"Young Adult",IF(E12<=40,"Adult",IF(E12<=60,"Senior Adult","Older Customer"))) -> Young Adult
A13: 12 | B13: 45229 | C13: CUST012 | D13: Male | E13: 35 | F13: Beauty | G13: 3 | H13: 25 | I13: 75 | J13: =G13*H13 -> 75 | K13: =IF(I13=J13,"Correct","Check") -> Correct | L13: =IF(E13<=25,"Young Adult",IF(E13<=40,"Adult",IF(E13<=60,"Senior Adult","Older Customer"))) -> Adult
A14: 13 | B14: 45143 | C14: CUST013 | D14: Male | E14: 22 | F14: Electronics | G14: 3 | H14: 500 | I14: 1500 | J14: =G14*H14 -> 1500 | K14: =IF(I14=J14,"Correct","Check") -> Correct | L14: =IF(E14<=25,"Young Adult",IF(E14<=40,"Adult",IF(E14<=60,"Senior Adult","Older Customer"))) -> Young Adult
A15: 14 | B15: 44943 | C15: CUST014 | D15: Male | E15: 64 | F15: Clothing | G15: 4 | H15: 30 | I15: 120 | J15: =G15*H15 -> 120 | K15: =IF(I15=J15,"Correct","Check") -> Correct | L15: =IF(E15<=25,"Young Adult",IF(E15<=40,"Adult",IF(E15<=60,"Senior Adult","Older Customer"))) -> Older Customer
A16: 15 | B16: 44942 | C16: CUST015 | D16: Female | E16: 42 | F16: Electronics | G16: 4 | H16: 500 | I16: 2000 | J16: =G16*H16 -> 2000 | K16: =IF(I16=J16,"Correct","Check") -> Correct | L16: =IF(E16<=25,"Young Adult",IF(E16<=40,"Adult",IF(E16<=60,"Senior Adult","Older Customer"))) -> Senior Adult
A17: 16 | B17: 44974 | C17: CUST016 | D17: Male | E17: 19 | F17: Clothing | G17: 3 | H17: 500 | I17: 1500 | J17: =G17*H17 -> 1500 | K17: =IF(I17=J17,"Correct","Check") -> Correct | L17: =IF(E17<=25,"Young Adult",IF(E17<=40,"Adult",IF(E17<=60,"Senior Adult","Older Customer"))) -> Young Adult
... A1001: 1000 | B1001: 45028 | C1001: CUST1000 | D1001: Male | E1001: 47 | F1001: Electronics | G1001: 4 | H1001: 30 | I1001: 120 | J1001: =G1001*H1001 -> 120 | K1001: =IF(I1001=J1001,"Correct","Check") -> Correct | L1001: =IF(E1001<=25,"Young Adult",IF(E1001<=40,"Adult",IF(E1001<=60,"Senior Adult","Older Customer"))) -> Senior Adult

Sheet Data Quality Check
A2: PART 3 : DATA QUALITY CHECK
A4: 1. Are there any blank cells in the sheet?
A5: Ans : | B5: No, there are no blank cells in the sheet | G5: =COUNTBLANK('Cleaned Data'!A2:H1001) -> 0
A6: 2. Are there any duplicate rows ?
A7: Ans : | B7: No, there are no duplicate rows
A8: 3. Are all values in the Quantity column valid?
A9: Ans : | B9: Yes, all values in the Quantity Column are valid
A10: 4. Are all values in the Price per Unit column valid?
A11: Ans : | B11: Yes, all values in hte Price per Unit are valid
A12: 5. Does Total Amount match this formula?
A13: Ans : | B13: Yes, the total amount matches the formula

Sheet Basic Analysis
A2: PART 4 : BASIC EXCEL FORMULAS
A4: No | B4: Basic Analysis | C4: Value
A5: 1 | B5: Total sales amount | C5: =SUM('Cleaned Data'!I2:I1001) -> 456000
A6: 2 | B6: Average sales amount | C6: =AVERAGE('Cleaned Data'!I2:I1001) -> 456
A7: 3 | B7: Minimum sales amount | C7: =MIN('Cleaned Data'!I2:I1001) -> 25
A8: 4 | B8: Maximum sales amount | C8: =MAX('Cleaned Data'!I2:I1001) -> 2000
A9: 5 | B9: Total quantity sold | C9: =SUM('Cleaned Data'!G2:G1001) -> 2514
A10: 6 | B10: Average customer age | C10: =AVERAGE('Cleaned Data'!E2:E1001) -> 41.392
A11: 7 | B11: Youngest customer age | C11: =MIN('Cleaned Data'!E2:E1001) -> 18
A12: 8 | B12: Oldest customer age | C12: =MAX('Cleaned Data'!E2:E1001) -> 64
A13: 9 | B13: Total number of transactions | C13: =COUNT('Cleaned Data'!A2:A1001) -> 1000
A14: 10 | B14: Total number of unique product categories | C14: 3
A15: 11 | B15: Average quantity sold | C15: =AVERAGE('Cleaned Data'!G2:G1001) -> 2.514
A17: PART 6 : SIMPLE CATEGORY - BASED ANALYSIS
B19: Total Sales by Product Category
B20: Product Category | C20: Total Sales
B21: Beauty | C21: =SUMIF('Cleaned Data'!F2:F1001,"Beauty",'Cleaned Data'!I2:I1001) -> 143515
B22: Clothing | C22: =SUMIF('Cleaned Data'!F2:F1001,"Clothing",'Cleaned Data'!I2:I1001) -> 155580
B23: Electronics | C23: =SUMIF('Cleaned Data'!F2:F1001,"Electronics",'Cleaned Data'!I2:I1001) -> 156905
B24: Total | C24: =SUM(C21:C23) -> 456000
B26: Total Quantity Sold by Product Category
B27: Product Category | C27: Quantity Sold
B28: Beauty | C28: =SUMIF('Cleaned Data'!F2:F1001,"Beauty",'Cleaned Data'!G2:G1001) -> 771
B29: Clothing | C29: =SUMIF('Cleaned Data'!F2:F1001,"Clothing",'Cleaned Data'!G2:G1001) -> 894
B30: Electronics | C30: =SUMIF('Cleaned Data'!F2:F1001,"Electronics",'Cleaned Data'!G2:G1001) -> 849
B31: Total | C31: =SUM(C28:C30) -> 2514
B33: Total Sales by Gender
B34: Gender | C34: Total Sales
B35: Male | C35: =SUMIF('Cleaned Data'!D2:D1001,"Male",'Cleaned Data'!I2:I1001) -> 223160
B36: Female | C36: =SUMIF('Cleaned Data'!D2:D1001,"Female",'Cleaned Data'!I2:I1001) -> 232840
B37: Total | C37: =SUM(C34:C36) -> 456000
B39: Total Sales by Age Group
B40: Age Group | C40: Total Sales
B41: Young Adult | C41: =SUMIF('Cleaned Data'!$L$2:$L$1001,"Young Adult",'Cleaned Data'!$I$2:$I$1001) -> 84550
B42: Adult | C42: =SUMIF('Cleaned Data'!$L$2:$L$1001,"Adult",'Cleaned Data'!$I$2:$I$1001) -> 144345
B43: Senior Adult | C43: =SUMIF('Cleaned Data'!$L$2:$L$1001,"Senior Adult",'Cleaned Data'!$I$2:$I$1001) -> 193880
B44: Older Customer | C44: =SUMIF('Cleaned Data'!$L$2:$L$1001,"Older Customer",'Cleaned Data'!$I$2:$I$1001) -> 33225
B45: Total | C45: =SUM(C41:C44) -> 456000
B47: Count of Product Category | C47: Column Labels
B48: Row Labels | C48: Beauty | D48: Clothing | E48: Electronics | F48: Grand Total
...

Sheet Sorting & Filtering Screenshots
A2: PART 5 : SORTING AND FILTERING
A4: No | B4: Questions
A5: 1 | B5: Which transaction has the highest total amount?
A6: 2 | B6: Which transaction has the lowest total amount?
A7: 3 | B7: Show only transactions where Product Category is Clothing.
A8: 4 | B8: Show only transactions where Gender is Female.
A9: 5 | B9: Show only transactions where Quantity is greater than 2.
A10: 6 | B10: Sort the dataset from highest Total Amount to lowest Total Amount.
A11: 7 | B11: Sort the dataset from youngest customer to oldest customer.
A13: Answer
A15: 1. | B15: Transactions with highest total amount
A35: 2 | B35: Transactions with lowest total amount
A55: 3 | B55: Show only transactions where Product Category is Clothing.
A75: 4 | B75: Show only transactions where Gender is Female.
A95: 5 | B95: Show only transactions where Quantity is greater than 2.
A115: 6 | B115: Sort the dataset from highest Total Amount to lowest Total Amount.
A135: 7 | B135: Sort the dataset from youngest customer to oldest customer.

Sheet Charts
A2: PART 7 : BASIC CHARTS
A4: SALES CHART
A6: Total Sales | F6: Total Quantity Sold | K6: Total Transaction | P6: Average Sales Amount | U6: Average Customer Age
A8: ='Basic Analysis'!C5 -> 456000 | F8: ='Basic Analysis'!C9 -> 2514 | K8: ='Basic Analysis'!C13 -> 1000 | P8: ='Basic Analysis'!C6 -> 456 | U8: ='Basic Analysis'!C10 -> 41.392

Sheet Observations
A2: PART 8 : WRITE SIMPLE OBSERVATIONS
A4: 1. The highest sales category is electronics
A5: 2. The lowest sales category is beauty
A6: 3. Female customers generated 232840 total sales
A7: 4. Male customers generated 223160 total sales
A8: 5. The average customer age is 41 y.o
A9: 6. The total quantity sold is 2514
A10: 7. The highest transaction amount is 2000
A11: 8. The average quantity sold per transaction is 3 unit
A12: 9. The highest quantity purchased category is clothing
A13: 10. The lowest quantity purchased category is beauty
A14: 11. Customers aged to 41 to 60 (Senior Adults) generated the highest total sales and the highest quantity of products
A15: 12. The senior adult age group (41 to 60) purchased the highest quantity of Clothing products
